2024-06-29 23:27:39,714 INFO    MainThread:32416 [wandb_setup.py:_flush():76] Current SDK version is 0.15.12
2024-06-29 23:27:39,714 INFO    MainThread:32416 [wandb_setup.py:_flush():76] Configure stats pid to 32416
2024-06-29 23:27:39,714 INFO    MainThread:32416 [wandb_setup.py:_flush():76] Loading settings from C:\Users\JiaPeng\.config\wandb\settings
2024-06-29 23:27:39,714 INFO    MainThread:32416 [wandb_setup.py:_flush():76] Loading settings from D:\BITcode\__code__\PJ_LML\wandb\settings
2024-06-29 23:27:39,714 INFO    MainThread:32416 [wandb_setup.py:_flush():76] Loading settings from environment variables: {}
2024-06-29 23:27:39,714 INFO    MainThread:32416 [wandb_setup.py:_flush():76] Applying setup settings: {'_disable_service': False}
2024-06-29 23:27:39,714 INFO    MainThread:32416 [wandb_setup.py:_flush():76] Inferring run settings from compute environment: {'program_relpath': 'train_wandb.py', 'program_abspath': 'D:\\BITcode\\__code__\\PJ_LML\\train_wandb.py', 'program': 'D:\\BITcode\\__code__\\PJ_LML\\train_wandb.py'}
2024-06-29 23:27:39,715 INFO    MainThread:32416 [wandb_init.py:_log_setup():528] Logging user logs to D:\BITcode\__code__\PJ_LML\wandb\run-20240629_232739-y8yr9jrd\logs\debug.log
2024-06-29 23:27:39,715 INFO    MainThread:32416 [wandb_init.py:_log_setup():529] Logging internal logs to D:\BITcode\__code__\PJ_LML\wandb\run-20240629_232739-y8yr9jrd\logs\debug-internal.log
2024-06-29 23:27:39,715 INFO    MainThread:32416 [wandb_init.py:init():568] calling init triggers
2024-06-29 23:27:39,715 INFO    MainThread:32416 [wandb_init.py:init():575] wandb.init called with sweep_config: {}
config: {'noise_factor': 0, 'architecture': 'ResNet50', 'dataset': 'MNIST', 'epochs': 1000, 'batch_size': 64, 'learning_rate': 0.001}
2024-06-29 23:27:39,715 INFO    MainThread:32416 [wandb_init.py:init():618] starting backend
2024-06-29 23:27:39,715 INFO    MainThread:32416 [wandb_init.py:init():622] setting up manager
2024-06-29 23:27:39,717 INFO    MainThread:32416 [backend.py:_multiprocessing_setup():105] multiprocessing start_methods=spawn, using: spawn
2024-06-29 23:27:39,719 INFO    MainThread:32416 [wandb_init.py:init():628] backend started and connected
2024-06-29 23:27:39,722 INFO    MainThread:32416 [wandb_init.py:init():720] updated telemetry
2024-06-29 23:27:39,724 INFO    MainThread:32416 [wandb_init.py:init():753] communicating run to backend with 90.0 second timeout
2024-06-29 23:27:42,381 INFO    MainThread:32416 [wandb_run.py:_on_init():2220] communicating current version
2024-06-29 23:27:47,397 INFO    MainThread:32416 [wandb_run.py:_on_init():2229] got version response 
2024-06-29 23:27:47,397 INFO    MainThread:32416 [wandb_init.py:init():804] starting run threads in backend
2024-06-29 23:27:56,435 INFO    MainThread:32416 [wandb_run.py:_console_start():2199] atexit reg
2024-06-29 23:27:56,435 INFO    MainThread:32416 [wandb_run.py:_redirect():2054] redirect: wrap_raw
2024-06-29 23:27:56,435 INFO    MainThread:32416 [wandb_run.py:_redirect():2119] Wrapping output streams.
2024-06-29 23:27:56,435 INFO    MainThread:32416 [wandb_run.py:_redirect():2144] Redirects installed.
2024-06-29 23:27:56,436 INFO    MainThread:32416 [wandb_init.py:init():845] run started, returning control to user process
2024-06-29 23:50:27,795 INFO    MainThread:32416 [retry.py:__call__():172] Retry attempt failed:
Traceback (most recent call last):
  File "D:\Anaconda\envs\ML3.9\lib\site-packages\urllib3\connection.py", line 174, in _new_conn
    conn = connection.create_connection(
  File "D:\Anaconda\envs\ML3.9\lib\site-packages\urllib3\util\connection.py", line 95, in create_connection
    raise err
  File "D:\Anaconda\envs\ML3.9\lib\site-packages\urllib3\util\connection.py", line 85, in create_connection
    sock.connect(sa)
socket.timeout: timed out

During handling of the above exception, another exception occurred:

Traceback (most recent call last):
  File "D:\Anaconda\envs\ML3.9\lib\site-packages\urllib3\connectionpool.py", line 714, in urlopen
    httplib_response = self._make_request(
  File "D:\Anaconda\envs\ML3.9\lib\site-packages\urllib3\connectionpool.py", line 403, in _make_request
    self._validate_conn(conn)
  File "D:\Anaconda\envs\ML3.9\lib\site-packages\urllib3\connectionpool.py", line 1053, in _validate_conn
    conn.connect()
  File "D:\Anaconda\envs\ML3.9\lib\site-packages\urllib3\connection.py", line 363, in connect
    self.sock = conn = self._new_conn()
  File "D:\Anaconda\envs\ML3.9\lib\site-packages\urllib3\connection.py", line 179, in _new_conn
    raise ConnectTimeoutError(
urllib3.exceptions.ConnectTimeoutError: (<urllib3.connection.HTTPSConnection object at 0x0000025BA3882460>, 'Connection to api.wandb.ai timed out. (connect timeout=20)')

During handling of the above exception, another exception occurred:

Traceback (most recent call last):
  File "D:\Anaconda\envs\ML3.9\lib\site-packages\requests\adapters.py", line 486, in send
    resp = conn.urlopen(
  File "D:\Anaconda\envs\ML3.9\lib\site-packages\urllib3\connectionpool.py", line 798, in urlopen
    retries = retries.increment(
  File "D:\Anaconda\envs\ML3.9\lib\site-packages\urllib3\util\retry.py", line 592, in increment
    raise MaxRetryError(_pool, url, error or ResponseError(cause))
urllib3.exceptions.MaxRetryError: HTTPSConnectionPool(host='api.wandb.ai', port=443): Max retries exceeded with url: /graphql (Caused by ConnectTimeoutError(<urllib3.connection.HTTPSConnection object at 0x0000025BA3882460>, 'Connection to api.wandb.ai timed out. (connect timeout=20)'))

During handling of the above exception, another exception occurred:

Traceback (most recent call last):
  File "D:\Anaconda\envs\ML3.9\lib\site-packages\wandb\sdk\lib\retry.py", line 131, in __call__
    result = self._call_fn(*args, **kwargs)
  File "D:\Anaconda\envs\ML3.9\lib\site-packages\wandb\sdk\internal\internal_api.py", line 366, in execute
    return self.client.execute(*args, **kwargs)  # type: ignore
  File "D:\Anaconda\envs\ML3.9\lib\site-packages\wandb\vendor\gql-0.2.0\wandb_gql\client.py", line 52, in execute
    result = self._get_result(document, *args, **kwargs)
  File "D:\Anaconda\envs\ML3.9\lib\site-packages\wandb\vendor\gql-0.2.0\wandb_gql\client.py", line 60, in _get_result
    return self.transport.execute(document, *args, **kwargs)
  File "D:\Anaconda\envs\ML3.9\lib\site-packages\wandb\sdk\lib\gql_request.py", line 58, in execute
    request = self.session.post(self.url, **post_args)
  File "D:\Anaconda\envs\ML3.9\lib\site-packages\requests\sessions.py", line 637, in post
    return self.request("POST", url, data=data, json=json, **kwargs)
  File "D:\Anaconda\envs\ML3.9\lib\site-packages\requests\sessions.py", line 589, in request
    resp = self.send(prep, **send_kwargs)
  File "D:\Anaconda\envs\ML3.9\lib\site-packages\requests\sessions.py", line 703, in send
    r = adapter.send(request, **kwargs)
  File "D:\Anaconda\envs\ML3.9\lib\site-packages\requests\adapters.py", line 507, in send
    raise ConnectTimeout(e, request=request)
requests.exceptions.ConnectTimeout: HTTPSConnectionPool(host='api.wandb.ai', port=443): Max retries exceeded with url: /graphql (Caused by ConnectTimeoutError(<urllib3.connection.HTTPSConnection object at 0x0000025BA3882460>, 'Connection to api.wandb.ai timed out. (connect timeout=20)'))
2024-06-30 09:48:42,134 INFO    MainThread:32416 [wandb_run.py:_finish():1934] finishing run pengtutu/MNIST_Classification/y8yr9jrd
2024-06-30 09:48:42,134 INFO    MainThread:32416 [wandb_run.py:_atexit_cleanup():2168] got exitcode: 0
2024-06-30 09:48:42,134 INFO    MainThread:32416 [wandb_run.py:_restore():2151] restore
2024-06-30 09:48:42,134 INFO    MainThread:32416 [wandb_run.py:_restore():2157] restore done
2024-06-30 09:50:38,939 INFO    MainThread:32416 [wandb_run.py:_footer_history_summary_info():3599] rendering history
2024-06-30 09:50:38,939 INFO    MainThread:32416 [wandb_run.py:_footer_history_summary_info():3631] rendering summary
2024-06-30 09:50:38,944 INFO    MainThread:32416 [wandb_run.py:_footer_sync_info():3558] logging synced files
